Update "{'update_id': 851612943, 'message': {'message_id': 1211, 'date': 1610889935, 'chat': {'id': 236836382, 'type': 'private', 'username': 'dpooria75', 'first_name': 'Pooria', 'last_name': 'Dabbaghi'}, 'text': 'سلام چطوری', 'entities': [], 'caption_entities': [], 'photo': [], 'new_chat_members': [], 'new_chat_photo': [], 'delete_chat_photo': False, 'group_chat_created': False, 'supergroup_chat_created': False, 'channel_chat_created': False, 'from': {'id': 236836382, 'first_name': 'Pooria', 'is_bot': False, 'last_name': 'Dabbaghi', 'username': 'dpooria75', 'language_code': 'en'}}}" caused error "0"
Update "{'update_id': 851612945, 'callback_query': {'id': '1017204517977633266', 'chat_instance': '-8102354624202857770', 'message': {'message_id': 1213, 'date': 1610890124, 'chat': {'id': 236836382, 'type': 'private', 'username': 'dpooria75', 'first_name': 'Pooria', 'last_name': 'Dabbaghi'}, 'text': "نوع سوال: آب و هوا \n نام شهرها: ['شهرضا'] \n تاریخ: ['1399-10-28'] \n زمان: ['16:51'] \n اوقات شرعی: [] \n نوع تقویم: [] \n مناسبت\u200cها: [] \n جواب شما: ابری \n لطفا در زیر درست یا غلط بودن پاسخ را مشخص کنید", 'entities': [], 'caption_entities': [], 'photo': [], 'new_chat_members': [], 'new_chat_photo': [], 'delete_chat_photo': False, 'group_chat_created': False, 'supergroup_chat_created': False, 'channel_chat_created': False, 'reply_markup': {'inline_keyboard': [[{'text': '👍', 'callback_data': 'positive'}, {'text': '👎', 'callback_data': 'negative'}]]}, 'from': {'id': 1400856218, 'first_name': 'از من بپرس!', 'is_bot': True, 'username': 'dalphaaibot'}}, 'data': 'positive', 'from': {'id': 236836382, 'first_name': 'Pooria', 'is_bot': False, 'last_name': 'Dabbaghi', 'username': 'dpooria75', 'language_code': 'en'}}}" caused error "'NoneType' object has no attribute 'chat'"
Update "{'update_id': 851612947, 'callback_query': {'id': '1017204519084793086', 'chat_instance': '-8102354624202857770', 'message': {'message_id': 1215, 'date': 1610890499, 'chat': {'id': 236836382, 'type': 'private', 'username': 'dpooria75', 'first_name': 'Pooria', 'last_name': 'Dabbaghi'}, 'text': "نوع سوال: آب و هوا \n نام شهرها: ['شهرضا'] \n تاریخ: ['1399-10-28'] \n زمان: ['17:04'] \n اوقات شرعی: [] \n نوع تقویم: [] \n مناسبت\u200cها: [] \n جواب شما: ابری \n لطفا در زیر درست یا غلط بودن پاسخ را مشخص کنید", 'entities': [], 'caption_entities': [], 'photo': [], 'new_chat_members': [], 'new_chat_photo': [], 'delete_chat_photo': False, 'group_chat_created': False, 'supergroup_chat_created': False, 'channel_chat_created': False, 'reply_markup': {'inline_keyboard': [[{'text': '👍', 'callback_data': 'positive'}, {'text': '👎', 'callback_data': 'negative'}]]}, 'from': {'id': 1400856218, 'first_name': 'از من بپرس!', 'is_bot': True, 'username': 'dalphaaibot'}}, 'data': 'positive', 'from': {'id': 236836382, 'first_name': 'Pooria', 'is_bot': False, 'last_name': 'Dabbaghi', 'username': 'dpooria75', 'language_code': 'en'}}}" caused error "'CallbackQuery' object has no attribute 'sender_chat'"
Update "{'update_id': 851612948, 'callback_query': {'id': '1017204515441514273', 'chat_instance': '-8102354624202857770', 'message': {'message_id': 1215, 'date': 1610890499, 'chat': {'id': 236836382, 'type': 'private', 'username': 'dpooria75', 'first_name': 'Pooria', 'last_name': 'Dabbaghi'}, 'text': "نوع سوال: آب و هوا \n نام شهرها: ['شهرضا'] \n تاریخ: ['1399-10-28'] \n زمان: ['17:04'] \n اوقات شرعی: [] \n نوع تقویم: [] \n مناسبت\u200cها: [] \n جواب شما: ابری \n لطفا در زیر درست یا غلط بودن پاسخ را مشخص کنید", 'entities': [], 'caption_entities': [], 'photo': [], 'new_chat_members': [], 'new_chat_photo': [], 'delete_chat_photo': False, 'group_chat_created': False, 'supergroup_chat_created': False, 'channel_chat_created': False, 'reply_markup': {'inline_keyboard': [[{'text': '👍', 'callback_data': 'positive'}, {'text': '👎', 'callback_data': 'negative'}]]}, 'from': {'id': 1400856218, 'first_name': 'از من بپرس!', 'is_bot': True, 'username': 'dalphaaibot'}}, 'data': 'positive', 'from': {'id': 236836382, 'first_name': 'Pooria', 'is_bot': False, 'last_name': 'Dabbaghi', 'username': 'dpooria75', 'language_code': 'en'}}}" caused error "'NoneType' object has no attribute 'username'"
Update "{'update_id': 851612952, 'callback_query': {'id': '1017204515228257416', 'chat_instance': '-8102354624202857770', 'message': {'message_id': 1219, 'date': 1610892446, 'chat': {'id': 236836382, 'type': 'private', 'username': 'dpooria75', 'first_name': 'Pooria', 'last_name': 'Dabbaghi'}, 'text': "نوع سوال: اوقات شرعی \n نام شهرها: ['شهرضا'] \n تاریخ: ['1399-10-28'] \n زمان: [] \n اوقات شرعی: ['غروب آفتاب'] \n نوع تقویم: [] \n مناسبت\u200cها: [] \n جواب شما: 00:14 \n لطفا در زیر درست یا غلط بودن پاسخ را مشخص کنید", 'entities': [], 'caption_entities': [], 'photo': [], 'new_chat_members': [], 'new_chat_photo': [], 'delete_chat_photo': False, 'group_chat_created': False, 'supergroup_chat_created': False, 'channel_chat_created': False, 'reply_markup': {'inline_keyboard': [[{'text': '👍', 'callback_data': 'positive'}, {'text': '👎', 'callback_data': 'negative'}]]}, 'from': {'id': 1400856218, 'first_name': 'از من بپرس!', 'is_bot': True, 'username': 'dalphaaibot'}}, 'data': 'positive', 'from': {'id': 236836382, 'first_name': 'Pooria', 'is_bot': False, 'last_name': 'Dabbaghi', 'username': 'dpooria75', 'language_code': 'en'}}}" caused error "'Update' object has no attribute 'editMessageReplyMarkup'"
Update "{'update_id': 851612953, 'callback_query': {'id': '1017204515484920317', 'chat_instance': '-8102354624202857770', 'message': {'message_id': 1219, 'date': 1610892446, 'chat': {'id': 236836382, 'type': 'private', 'username': 'dpooria75', 'first_name': 'Pooria', 'last_name': 'Dabbaghi'}, 'text': "نوع سوال: اوقات شرعی \n نام شهرها: ['شهرضا'] \n تاریخ: ['1399-10-28'] \n زمان: [] \n اوقات شرعی: ['غروب آفتاب'] \n نوع تقویم: [] \n مناسبت\u200cها: [] \n جواب شما: 00:14 \n لطفا در زیر درست یا غلط بودن پاسخ را مشخص کنید", 'entities': [], 'caption_entities': [], 'photo': [], 'new_chat_members': [], 'new_chat_photo': [], 'delete_chat_photo': False, 'group_chat_created': False, 'supergroup_chat_created': False, 'channel_chat_created': False, 'reply_markup': {'inline_keyboard': [[{'text': '👍', 'callback_data': 'positive'}, {'text': '👎', 'callback_data': 'negative'}]]}, 'from': {'id': 1400856218, 'first_name': 'از من بپرس!', 'is_bot': True, 'username': 'dalphaaibot'}}, 'data': 'positive', 'from': {'id': 236836382, 'first_name': 'Pooria', 'is_bot': False, 'last_name': 'Dabbaghi', 'username': 'dpooria75', 'language_code': 'en'}}}" caused error "'CallbackContext' object has no attribute 'editMessageReplyMarkup'"
Update "None" caused error "urllib3 HTTPError HTTPSConnectionPool(host='api.telegram.org', port=443): Max retries exceeded with url: /bot1400856218:AAGt6WPlRxL-FmcB3dhO7PS-7ErVxCIni9c/getUpdates (Caused by ProxyError('Cannot connect to proxy.', timeout('timed out')))"
Update "None" caused error "urllib3 HTTPError HTTPSConnectionPool(host='api.telegram.org', port=443): Max retries exceeded with url: /bot1400856218:AAGt6WPlRxL-FmcB3dhO7PS-7ErVxCIni9c/getUpdates (Caused by ProxyError('Cannot connect to proxy.', timeout('timed out')))"
Update "None" caused error "urllib3 HTTPError HTTPSConnectionPool(host='api.telegram.org', port=443): Max retries exceeded with url: /bot1400856218:AAGt6WPlRxL-FmcB3dhO7PS-7ErVxCIni9c/getUpdates (Caused by ProxyError('Cannot connect to proxy.', timeout('timed out')))"
Update "None" caused error "urllib3 HTTPError HTTPSConnectionPool(host='api.telegram.org', port=443): Max retries exceeded with url: /bot1400856218:AAGt6WPlRxL-FmcB3dhO7PS-7ErVxCIni9c/getUpdates (Caused by ProxyError('Cannot connect to proxy.', timeout('timed out')))"
Update "None" caused error "urllib3 HTTPError HTTPSConnectionPool(host='api.telegram.org', port=443): Max retries exceeded with url: /bot1400856218:AAGt6WPlRxL-FmcB3dhO7PS-7ErVxCIni9c/getUpdates (Caused by ProxyError('Cannot connect to proxy.', timeout('timed out')))"
Update "None" caused error "urllib3 HTTPError HTTPSConnectionPool(host='api.telegram.org', port=443): Max retries exceeded with url: /bot1400856218:AAGt6WPlRxL-FmcB3dhO7PS-7ErVxCIni9c/getUpdates (Caused by ProxyError('Cannot connect to proxy.', timeout('timed out')))"
Update "None" caused error "urllib3 HTTPError HTTPSConnectionPool(host='api.telegram.org', port=443): Max retries exceeded with url: /bot1400856218:AAGt6WPlRxL-FmcB3dhO7PS-7ErVxCIni9c/getUpdates (Caused by ProxyError('Cannot connect to proxy.', timeout('timed out')))"
Update "None" caused error "urllib3 HTTPError HTTPSConnectionPool(host='api.telegram.org', port=443): Max retries exceeded with url: /bot1400856218:AAGt6WPlRxL-FmcB3dhO7PS-7ErVxCIni9c/getUpdates (Caused by ProxyError('Cannot connect to proxy.', timeout('timed out')))"
Update "None" caused error "urllib3 HTTPError HTTPSConnectionPool(host='api.telegram.org', port=443): Max retries exceeded with url: /bot1400856218:AAGt6WPlRxL-FmcB3dhO7PS-7ErVxCIni9c/getUpdates (Caused by ProxyError('Cannot connect to proxy.', timeout('timed out')))"
Update "None" caused error "urllib3 HTTPError HTTPSConnectionPool(host='api.telegram.org', port=443): Max retries exceeded with url: /bot1400856218:AAGt6WPlRxL-FmcB3dhO7PS-7ErVxCIni9c/getUpdates (Caused by ProxyError('Cannot connect to proxy.', timeout('timed out')))"
Update "None" caused error "urllib3 HTTPError HTTPSConnectionPool(host='api.telegram.org', port=443): Max retries exceeded with url: /bot1400856218:AAGt6WPlRxL-FmcB3dhO7PS-7ErVxCIni9c/getUpdates (Caused by ProxyError('Cannot connect to proxy.', timeout('timed out')))"
Update "None" caused error "urllib3 HTTPError HTTPSConnectionPool(host='api.telegram.org', port=443): Max retries exceeded with url: /bot1400856218:AAGt6WPlRxL-FmcB3dhO7PS-7ErVxCIni9c/getUpdates (Caused by ProxyError('Cannot connect to proxy.', timeout('timed out')))"
Update "None" caused error "urllib3 HTTPError HTTPSConnectionPool(host='api.telegram.org', port=443): Max retries exceeded with url: /bot1400856218:AAGt6WPlRxL-FmcB3dhO7PS-7ErVxCIni9c/getUpdates (Caused by ProxyError('Cannot connect to proxy.', timeout('timed out')))"
Update "{'update_id': 851612954, 'callback_query': {'id': '1017204518082306905', 'chat_instance': '-8102354624202857770', 'message': {'message_id': 1219, 'date': 1610892446, 'chat': {'id': 236836382, 'type': 'private', 'username': 'dpooria75', 'first_name': 'Pooria', 'last_name': 'Dabbaghi'}, 'text': "نوع سوال: اوقات شرعی \n نام شهرها: ['شهرضا'] \n تاریخ: ['1399-10-28'] \n زمان: [] \n اوقات شرعی: ['غروب آفتاب'] \n نوع تقویم: [] \n مناسبت\u200cها: [] \n جواب شما: 00:14 \n لطفا در زیر درست یا غلط بودن پاسخ را مشخص کنید", 'entities': [], 'caption_entities': [], 'photo': [], 'new_chat_members': [], 'new_chat_photo': [], 'delete_chat_photo': False, 'group_chat_created': False, 'supergroup_chat_created': False, 'channel_chat_created': False, 'reply_markup': {'inline_keyboard': [[{'text': '👍', 'callback_data': 'positive'}, {'text': '👎', 'callback_data': 'negative'}]]}, 'from': {'id': 1400856218, 'first_name': 'از من بپرس!', 'is_bot': True, 'username': 'dalphaaibot'}}, 'data': 'positive', 'from': {'id': 236836382, 'first_name': 'Pooria', 'is_bot': False, 'last_name': 'Dabbaghi', 'username': 'dpooria75', 'language_code': 'en'}}}" caused error "'CallbackQuery' object has no attribute 'editMessageReplyMarkup'"
Update "{'update_id': 851612955, 'callback_query': {'id': '1017204517024761037', 'chat_instance': '-8102354624202857770', 'message': {'message_id': 1217, 'date': 1610891372, 'chat': {'id': 236836382, 'type': 'private', 'username': 'dpooria75', 'first_name': 'Pooria', 'last_name': 'Dabbaghi'}, 'text': "نوع سوال: تقویم \n نام شهرها: [] \n تاریخ: ['1399-10-29'] \n زمان: [] \n اوقات شرعی: [] \n نوع تقویم: [] \n مناسبت\u200cها: [] \n جواب شما: مناسبتی وجود ندارد \n لطفا در زیر درست یا غلط بودن پاسخ را مشخص کنید", 'entities': [], 'caption_entities': [], 'photo': [], 'new_chat_members': [], 'new_chat_photo': [], 'delete_chat_photo': False, 'group_chat_created': False, 'supergroup_chat_created': False, 'channel_chat_created': False, 'reply_markup': {'inline_keyboard': [[{'text': '👍', 'callback_data': 'positive'}, {'text': '👎', 'callback_data': 'negative'}]]}, 'from': {'id': 1400856218, 'first_name': 'از من بپرس!', 'is_bot': True, 'username': 'dalphaaibot'}}, 'data': 'positive', 'from': {'id': 236836382, 'first_name': 'Pooria', 'is_bot': False, 'last_name': 'Dabbaghi', 'username': 'dpooria75', 'language_code': 'en'}}}" caused error "edit_message_reply_markup() got multiple values for keyword argument 'chat_id'"
Update "{'update_id': 851612956, 'callback_query': {'id': '1017204515436216755', 'chat_instance': '-8102354624202857770', 'message': {'message_id': 1219, 'date': 1610892446, 'chat': {'id': 236836382, 'type': 'private', 'username': 'dpooria75', 'first_name': 'Pooria', 'last_name': 'Dabbaghi'}, 'text': "نوع سوال: اوقات شرعی \n نام شهرها: ['شهرضا'] \n تاریخ: ['1399-10-28'] \n زمان: [] \n اوقات شرعی: ['غروب آفتاب'] \n نوع تقویم: [] \n مناسبت\u200cها: [] \n جواب شما: 00:14 \n لطفا در زیر درست یا غلط بودن پاسخ را مشخص کنید", 'entities': [], 'caption_entities': [], 'photo': [], 'new_chat_members': [], 'new_chat_photo': [], 'delete_chat_photo': False, 'group_chat_created': False, 'supergroup_chat_created': False, 'channel_chat_created': False, 'reply_markup': {'inline_keyboard': [[{'text': '👍', 'callback_data': 'positive'}, {'text': '👎', 'callback_data': 'negative'}]]}, 'from': {'id': 1400856218, 'first_name': 'از من بپرس!', 'is_bot': True, 'username': 'dalphaaibot'}}, 'data': 'positive', 'from': {'id': 236836382, 'first_name': 'Pooria', 'is_bot': False, 'last_name': 'Dabbaghi', 'username': 'dpooria75', 'language_code': 'en'}}}" caused error "edit_message_reply_markup() got multiple values for keyword argument 'chat_id'"
Update "{'update_id': 851612958, 'callback_query': {'id': '1017204519425059934', 'chat_instance': '-8102354624202857770', 'message': {'message_id': 1219, 'date': 1610892446, 'chat': {'id': 236836382, 'type': 'private', 'username': 'dpooria75', 'first_name': 'Pooria', 'last_name': 'Dabbaghi'}, 'edit_date': 1610893971, 'text': "نوع سوال: اوقات شرعی \n نام شهرها: ['شهرضا'] \n تاریخ: ['1399-10-28'] \n زمان: [] \n اوقات شرعی: ['غروب آفتاب'] \n نوع تقویم: [] \n مناسبت\u200cها: [] \n جواب شما: 00:14 \n لطفا در زیر درست یا غلط بودن پاسخ را مشخص کنید", 'entities': [], 'caption_entities': [], 'photo': [], 'new_chat_members': [], 'new_chat_photo': [], 'delete_chat_photo': False, 'group_chat_created': False, 'supergroup_chat_created': False, 'channel_chat_created': False, 'reply_markup': {'inline_keyboard': [[{'text': 'ممنون از شما!', 'callback_data': 'Null'}]]}, 'from': {'id': 1400856218, 'first_name': 'از من بپرس!', 'is_bot': True, 'username': 'dalphaaibot'}}, 'data': 'Null', 'from': {'id': 236836382, 'first_name': 'Pooria', 'is_bot': False, 'last_name': 'Dabbaghi', 'username': 'dpooria75', 'language_code': 'en'}}}" caused error "Message is not modified: specified new message content and reply markup are exactly the same as a current content and reply markup of the message"
